Workbook

Sheet Solution Notes
A1: Day 26 Solution - Data Quality & Auditing
A2: Data: 'Returns Audit' sheet, 2500 rows. Built 2026-07-03.
A4: Task 1: Flag Missing Product Codes or Return Reasons.
A5: Sheet: 'Returns Audit (Solved)', column J.
A6: Formula (J2): =IF(OR(ISBLANK(C2),ISBLANK(D2)),"Missing","")
A7: ANSWER: 247 rows flagged Missing (pandas cross-check: Product Code blank OR Return Reason blank - matches).
A9: Task 2: Identify Duplicate Return IDs.
A10: Sheet: 'Returns Audit (Solved)', column K.
A11: Formula (K2): =IF(COUNTIF($A$2:$A$2501,A2)>1,"Duplicate","")
A12: ANSWER: 270 rows flagged Duplicate (270 rows belonging to 128 Return IDs that each appear more than once - pandas cross-check matches).
A14: Task 3: Flag Unusual Refund Amounts.
A15: Sheet: 'Returns Audit (Solved)', column L. 'Unusual' = $0 (no refund actually issued) or over $10,000.
... A42: ANSWER (counts as at build time): Missing (Product Code / Return Reason)=247, Duplicate Return ID=270, Unusual Refund Amount=610, Invalid Customer Email=462, Invalid Country=1378, Outdated Return Date=2444, Inconsistent Return Reason=356.

Sheet Instructions
A1: Instructions
A2: Day 26 - Data Quality Audit Exercise
A4: Scenario:
A5: You've been asked to audit the Returns and Damaged Goods data before presenting to Finance.
A6: Some fields may be missing, inconsistent or duplicated.
A8: Task | B8: Description
A9: 🔧 Task 1: Flag Missing Product Codes or Return Reasons | B9: Check if 'Product Code' or 'Return Reason' is blank. If so, flag the row as 'Missing'.
A10: 🔧 Task 2: Identify Duplicate Return IDs | B10: Check if 'Return ID' appears more than once. Flag these as 'Duplicate'.
A11: 🔧 Task 3: Flag Unusual Refund Amounts | B11: If 'Refund Amount ($)' is 0 or unusually high (e.g., over $10,000), flag it as 'Unusual'.
A12: 🔧 Task 4: Highlight Invalid Customer Emails | B12: Check if 'Customer Email' is missing or does not contain '@' and a domain. Flag as 'Invalid'.
A13: 🔧 Task 5: Spot Invalid Countries | B13: Validate 'Country' against this list: USA, Canada, UK, Australia, Germany. Others should be flagged as 'Invalid'.
A14: 🔧 Task 6: Check for Outdated Return Dates | B14: Flag any 'Return Date' that is older than 12 months from today.
A15: 🔧 Task 7: Catch Inconsistent Return Reasons | B15: Standardize 'Return Reason' values (e.g., wrong item, damaged). Flag any with typos or inconsistent casing.
A16: 🔧 Task 8: Build Data Quality Summary | B16: Create a table summarizing the count of each flagged issue and visualize it using a bar and pie chart.
A18: Optional:
A19: - Create a bar chart showing number of issues per category.
A20: - Create a pie chart showing which issue type is most common.
A22: Goal:
A23: To practice data auditing and gain confidence in spotting data quality issues before presenting to stakeholders.

Sheet Returns Audit
A1: Return ID | B1: Customer Name | C1: Product Code | D1: Return Reason | E1: Refund Amount ($) | F1: Return Date | G1: Customer Email | H1: Country | I1: Product Category
A2: R-1000 | B2: Kwame Patel | C2: P-960 | D2: Wrong Item | E2: 8617.22 | F2: 45782.667 | G2: kwame.patel@example.com | H2: UK | I2: Beauty
A3: R-1001 | B3: Elena Sato | C3: P-171 | D3: Wrong Item | E3: 11373.23 | F3: 45242.667 | H3: USA | I3: Homeware
A4: R-1002 | B4: Elena Sato | C4: P-714 | D4: Late Delivery | E4: 0 | F4: 45153.667 | G4: elena.sato@example.com | H4: Canaada | I4: Books
A5: R-1003 | B5: Samuel Gomez | C5: P-314 | D5: Not As Described | E5: 2084.06 | F5: 45409.667 | G5: samuel.gomez@example.com | I5: Homeware
A6: R-1004 | B6: Zara Williams | C6: P-187 | D6: Wrong Item | E6: 7747.15 | F6: 45378.667 | G6: zara.williams@example.com | H6: Canaada | I6: Books
A7: R-1005 | B7: Lucia Khan | C7: P-971 | D7: Damaged | E7: 8794.53 | F7: 45356.667 | G7: lucia.khan@example.com | I7: Books
A8: R-1006 | B8: Omar Silva | C8: P-761 | D8: damaged | E8: 11901.98 | F8: 45270.667 | H8: Germany | I8: Books
A9: R-1007 | B9: Mei Patel | C9: P-443 | D9: Damaged | E9: 9998.3 | F9: 45232.667 | G9: mei.patel@example.com | H9: UK | I9: Clothing
A10: R-1008 | B10: Omar Silva | C10: P-905 | D10: Damaged | E10: 7784.82 | F10: 45820.667 | G10: omar.silva@example.com | H10: Canada | I10: Beauty
A11: R-1009 | B11: Lucia Khan | E11: 7605.05 | F11: 45686.667 | G11: lucia.khan@example.com | H11: U.S.A. | I11: Electronics
A12: R-1010 | B12: Mei Patel | C12: P-260 | D12: Wrong Item | E12: 5315.41 | F12: 45217.667 | G12: mei.patel@example.com | H12: UK | I12: Beauty
A13: R-2813 | B13: Samuel Gomez | C13: P-121 | D13: Late Delivery | E13: 10188.53 | F13: 45732.667 | G13: samuel.gomez@example.com | I13: Electronics
A14: R-1012 | B14: Lucia Khan | D14: Damaged | E14: 11024.97 | F14: 45560.667 | G14: lucia.khan@example.com | H14: Canada | I14: Clothing
A15: R-2305 | B15: Zara Williams | D15: Damaged | E15: 6585.36 | F15: 45160.667 | G15: zara.williams@example.com | H15: USA | I15: Electronics
A16: R-2181 | B16: Lucia Khan | C16: P-610 | D16: Damaged | E16: 6996.81 | F16: 45158.667 | G16: lucia.khan@example.com | H16: Earth | I16: Clothing
A17: R-1015 | B17: Zara Williams | C17: P-575 | D17: Wrong Item | E17: 7924.03 | F17: 45223.667 | G17: zara.williams@example.com | H17: Canaada | I17: Clothing
A18: R-1016 | B18: Lucia Khan | C18: P-882 | D18: Damaged | E18: 283.1 | F18: 45351.667 | G18: lucia.khan@example.com | H18: Mars | I18: Homeware
A19: R-1017 | B19: Lucia Khan | C19: P-786 | D19: Wrong Item | E19: 3590.98 | F19: 45366.667 | G19: lucia.khan@example.com | H19: UAE | I19: Clothing
A20: R-1018 | B20: Nina Ivanov | C20: P-975 | D20: Not As Described | E20: 2499.33 | F20: 45645.667 | G20: nina.ivanov@example.com | H20: Mars | I20: Clothing
A21: R-1019 | B21: Omar Silva | C21: P-931 | D21: Damaged | E21: 2274.23 | F21: 45744.667 | G21: omar.silva@example.com | H21: Canada | I21: Books
A22: R-1020 | B22: Elena Sato | C22: P-584 | D22: Damaged | E22: 3732.08 | F22: 45155.667 | G22: elena.sato@example.com | H22: Australia | I22: Books
A23: R-1021 | B23: Nina Ivanov | C23: P-120 | D23: Wrong item | E23: 9299.14 | F23: 45702.667 | G23: nina.ivanov@example.com | H23: Australia | I23: Clothing
A24: R-1022 | B24: Elena Sato | C24: P-373 | D24: Not As Described | E24: 9568.04 | F24: 45331.667 | G24: elena.sato@example.com | H24: Australia | I24: Books
A25: R-1023 | B25: Nina Ivanov | C25: P-415 | D25: Wrong Item | E25: 10649.3 | F25: 45793.667 | G25: nina.ivanov@example.com | H25: Germany | I25: Homeware
A26: R-1024 | B26: Kwame Patel | C26: P-876 | D26: DAMAGED | E26: 4036.15 | F26: 45846.667 | G26: kwame.patel@example.com | H26: Germany | I26: Homeware
A27: R-2141 | B27: Mei Patel | D27: Wrong Item | E27: 1234.86 | F27: 45686.667 | G27: mei.patel@example.com | H27: Mars | I27: Clothing
A28: R-1026 | B28: Zara Williams | C28: P-191 | D28: Wrong Item | E28: 4646.95 | F28: 45557.667 | G28: zara.williams@example.com | H28: Canaada | I28: Beauty
A29: R-1027 | B29: Nina Ivanov | C29: P-554 | D29: Not As Described | E29: 5914.76 | F29: 45353.667 | G29: nina.ivanov@example.com | H29: UK | I29: Books
A30: R-1028 | B30: Nina Ivanov | C30: P-875 | D30: Late Delivery | E30: 8817.14 | F30: 45587.667 | G30: nina.ivanov@example.com | H30: Canaada | I30: Toys
A31: R-2327 | B31: Samuel Gomez | D31: Damaged | E31: 5889.72 | F31: 45731.667 | G31: samuel.gomez@example.com | H31: Australia | I31: Electronics
A32: R-1030 | B32: Lucia Khan | C32: P-661 | D32: Wrong Item | E32: 0 | F32: 45412.667 | G32: lucia.khan@example.com | I32: Books
A33: R-1031 | B33: Kwame Patel | C33: P-101 | D33: Late Delivery | E33: 7990.29 | F33: 45134.667 | G33: kwame.patel@example.com | H33: Australia | I33: Homeware
A34: R-1032 | B34: Mei Patel | C34: P-665 | D34: Damaged | E34: 11453.07 | F34: 45291.667 | G34: mei.patel@example.com | H34: Germany | I34: Homeware
A35: R-1033 | B35: Victor Adu | C35: P-921 | D35: DAMAGED | E35: 8495.29 | F35: 45842.667 | G35: victor.adu@example.com | H35: UAE | I35: Toys
A36: R-1034 | B36: Nina Ivanov | D36: Wrong Item | E36: 3028.82 | F36: 45560.667 | H36: Australia | I36: Beauty
A37: R-1035 | B37: Victor Adu | C37: P-655 | D37: Wrong item | E37: 2378.48 | F37: 45476.667 | G37: victor.adu@example.com | H37: Canaada | I37: Clothing
A38: R-1036 | B38: Elena Sato | C38: P-369 | D38: Late Delivery | E38: 11993.61 | F38: 45412.667 | G38: elena.sato@example.com | H38: UK | I38: Toys
A39: R-2750 | B39: Lucia Khan | C39: P-370 | E39: 5171.85 | F39: 45287.667 | H39: Canaada | I39: Toys
A40: R-3494 | B40: Victor Adu | C40: P-826 | D40: Not As Described | E40: 7247.05 | F40: 45348.667 | G40: victor.adu@example.com | H40: UK | I40: Electronics
...

Sheet Returns Audit (Solved)
A1: Return ID | B1: Customer Name | C1: Product Code | D1: Return Reason | E1: Refund Amount ($) | F1: Return Date | G1: Customer Email | H1: Country | I1: Product Category | J1: Missing Flag | K1: Duplicate Flag | L1: Unusual Refund Flag | M1: Invalid Email Flag | N1: Invalid Country Flag | O1: Outdated Return Flag | P1: Standardized Return Reason | Q1: Inconsistent Reason Flag | S1: Valid Countries
A2: R-1000 | B2: Kwame Patel | C2: P-960 | D2: Wrong Item | E2: 8617.22 | F2: 45782.667 | G2: kwame.patel@example.com | H2: UK | I2: Beauty | J2: =IF(OR(ISBLANK(C2),ISBLANK(D2)),"Missing","") | K2: =IF(COUNTIF($A$2:$A$2501,A2)>1,"Duplicate","") | L2: =IF(OR(E2=0,E2>10000),"Unusual","") | M2: =IF(OR(ISBLANK(G2),ISERROR(FIND("@",G2)),ISERROR(FIND(".",G2,FIND("@",G2)+1))),"Invalid","") | N2: =IF(COUNTIF($S$2:$S$6,H2)=0,"Invalid","") | O2: =IF(F2<EDATE(TODAY(),-12),"Outdated","") -> Outdated | P2: =IF(ISBLANK(D2),"",PROPER(TRIM(D2))) -> Wrong Item | Q2: =IF(ISBLANK(D2),"",IF(EXACT(D2,P2),"","Inconsistent")) | S2: USA
A3: R-1001 | B3: Elena Sato | C3: P-171 | D3: Wrong Item | E3: 11373.23 | F3: 45242.667 | H3: USA | I3: Homeware | J3: =IF(OR(ISBLANK(C3),ISBLANK(D3)),"Missing","") | K3: =IF(COUNTIF($A$2:$A$2501,A3)>1,"Duplicate","") | L3: =IF(OR(E3=0,E3>10000),"Unusual","") -> Unusual | M3: =IF(OR(ISBLANK(G3),ISERROR(FIND("@",G3)),ISERROR(FIND(".",G3,FIND("@",G3)+1))),"Invalid","") -> Invalid | N3: =IF(COUNTIF($S$2:$S$6,H3)=0,"Invalid","") | O3: =IF(F3<EDATE(TODAY(),-12),"Outdated","") -> Outdated | P3: =IF(ISBLANK(D3),"",PROPER(TRIM(D3))) -> Wrong Item | Q3: =IF(ISBLANK(D3),"",IF(EXACT(D3,P3),"","Inconsistent")) | S3: Canada
A4: R-1002 | B4: Elena Sato | C4: P-714 | D4: Late Delivery | E4: 0 | F4: 45153.667 | G4: elena.sato@example.com | H4: Canaada | I4: Books | J4: =IF(OR(ISBLANK(C4),ISBLANK(D4)),"Missing","") | K4: =IF(COUNTIF($A$2:$A$2501,A4)>1,"Duplicate","") | L4: =IF(OR(E4=0,E4>10000),"Unusual","") -> Unusual | M4: =IF(OR(ISBLANK(G4),ISERROR(FIND("@",G4)),ISERROR(FIND(".",G4,FIND("@",G4)+1))),"Invalid","") | N4: =IF(COUNTIF($S$2:$S$6,H4)=0,"Invalid","") -> Invalid | O4: =IF(F4<EDATE(TODAY(),-12),"Outdated","") -> Outdated | P4: =IF(ISBLANK(D4),"",PROPER(TRIM(D4))) -> Late Delivery | Q4: =IF(ISBLANK(D4),"",IF(EXACT(D4,P4),"","Inconsistent")) | S4: UK
A5: R-1003 | B5: Samuel Gomez | C5: P-314 | D5: Not As Described | E5: 2084.06 | F5: 45409.667 | G5: samuel.gomez@example.com | I5: Homeware | J5: =IF(OR(ISBLANK(C5),ISBLANK(D5)),"Missing","") | K5: =IF(COUNTIF($A$2:$A$2501,A5)>1,"Duplicate","") | L5: =IF(OR(E5=0,E5>10000),"Unusual","") | M5: =IF(OR(ISBLANK(G5),ISERROR(FIND("@",G5)),ISERROR(FIND(".",G5,FIND("@",G5)+1))),"Invalid","") | N5: =IF(COUNTIF($S$2:$S$6,H5)=0,"Invalid","") -> Invalid | O5: =IF(F5<EDATE(TODAY(),-12),"Outdated","") -> Outdated | P5: =IF(ISBLANK(D5),"",PROPER(TRIM(D5))) -> Not As Described | Q5: =IF(ISBLANK(D5),"",IF(EXACT(D5,P5),"","Inconsistent")) | S5: Australia
A6: R-1004 | B6: Zara Williams | C6: P-187 | D6: Wrong Item | E6: 7747.15 | F6: 45378.667 | G6: zara.williams@example.com | H6: Canaada | I6: Books | J6: =IF(OR(ISBLANK(C6),ISBLANK(D6)),"Missing","") | K6: =IF(COUNTIF($A$2:$A$2501,A6)>1,"Duplicate","") | L6: =IF(OR(E6=0,E6>10000),"Unusual","") | M6: =IF(OR(ISBLANK(G6),ISERROR(FIND("@",G6)),ISERROR(FIND(".",G6,FIND("@",G6)+1))),"Invalid","") | N6: =IF(COUNTIF($S$2:$S$6,H6)=0,"Invalid","") -> Invalid | O6: =IF(F6<EDATE(TODAY(),-12),"Outdated","") -> Outdated | P6: =IF(ISBLANK(D6),"",PROPER(TRIM(D6))) -> Wrong Item | Q6: =IF(ISBLANK(D6),"",IF(EXACT(D6,P6),"","Inconsistent")) | S6: Germany
A7: R-1005 | B7: Lucia Khan | C7: P-971 | D7: Damaged | E7: 8794.53 | F7: 45356.667 | G7: lucia.khan@example.com | I7: Books | J7: =IF(OR(ISBLANK(C7),ISBLANK(D7)),"Missing","") | K7: =IF(COUNTIF($A$2:$A$2501,A7)>1,"Duplicate","") | L7: =IF(OR(E7=0,E7>10000),"Unusual","") | M7: =IF(OR(ISBLANK(G7),ISERROR(FIND("@",G7)),ISERROR(FIND(".",G7,FIND("@",G7)+1))),"Invalid","") | N7: =IF(COUNTIF($S$2:$S$6,H7)=0,"Invalid","") -> Invalid | O7: =IF(F7<EDATE(TODAY(),-12),"Outdated","") -> Outdated | P7: =IF(ISBLANK(D7),"",PROPER(TRIM(D7))) -> Damaged | Q7: =IF(ISBLANK(D7),"",IF(EXACT(D7,P7),"","Inconsistent"))
A8: R-1006 | B8: Omar Silva | C8: P-761 | D8: damaged | E8: 11901.98 | F8: 45270.667 | H8: Germany | I8: Books | J8: =IF(OR(ISBLANK(C8),ISBLANK(D8)),"Missing","") | K8: =IF(COUNTIF($A$2:$A$2501,A8)>1,"Duplicate","") | L8: =IF(OR(E8=0,E8>10000),"Unusual","") -> Unusual | M8: =IF(OR(ISBLANK(G8),ISERROR(FIND("@",G8)),ISERROR(FIND(".",G8,FIND("@",G8)+1))),"Invalid","") -> Invalid | N8: =IF(COUNTIF($S$2:$S$6,H8)=0,"Invalid","") | O8: =IF(F8<EDATE(TODAY(),-12),"Outdated","") -> Outdated | P8: =IF(ISBLANK(D8),"",PROPER(TRIM(D8))) -> Damaged | Q8: =IF(ISBLANK(D8),"",IF(EXACT(D8,P8),"","Inconsistent")) -> Inconsistent
A9: R-1007 | B9: Mei Patel | C9: P-443 | D9: Damaged | E9: 9998.3 | F9: 45232.667 | G9: mei.patel@example.com | H9: UK | I9: Clothing | J9: =IF(OR(ISBLANK(C9),ISBLANK(D9)),"Missing","") | K9: =IF(COUNTIF($A$2:$A$2501,A9)>1,"Duplicate","") -> Duplicate | L9: =IF(OR(E9=0,E9>10000),"Unusual","") | M9: =IF(OR(ISBLANK(G9),ISERROR(FIND("@",G9)),ISERROR(FIND(".",G9,FIND("@",G9)+1))),"Invalid","") | N9: =IF(COUNTIF($S$2:$S$6,H9)=0,"Invalid","") | O9: =IF(F9<EDATE(TODAY(),-12),"Outdated","") -> Outdated | P9: =IF(ISBLANK(D9),"",PROPER(TRIM(D9))) -> Damaged | Q9: =IF(ISBLANK(D9),"",IF(EXACT(D9,P9),"","Inconsistent"))
A10: R-1008 | B10: Omar Silva | C10: P-905 | D10: Damaged | E10: 7784.82 | F10: 45820.667 | G10: omar.silva@example.com | H10: Canada | I10: Beauty | J10: =IF(OR(ISBLANK(C10),ISBLANK(D10)),"Missing","") | K10: =IF(COUNTIF($A$2:$A$2501,A10)>1,"Duplicate","") | L10: =IF(OR(E10=0,E10>10000),"Unusual","") | M10: =IF(OR(ISBLANK(G10),ISERROR(FIND("@",G10)),ISERROR(FIND(".",G10,FIND("@",G10)+1))),"Invalid","") | N10: =IF(COUNTIF($S$2:$S$6,H10)=0,"Invalid","") | O10: =IF(F10<EDATE(TODAY(),-12),"Outdated","") -> Outdated | P10: =IF(ISBLANK(D10),"",PROPER(TRIM(D10))) -> Damaged | Q10: =IF(ISBLANK(D10),"",IF(EXACT(D10,P10),"","Inconsistent"))
A11: R-1009 | B11: Lucia Khan | E11: 7605.05 | F11: 45686.667 | G11: lucia.khan@example.com | H11: U.S.A. | I11: Electronics | J11: =IF(OR(ISBLANK(C11),ISBLANK(D11)),"Missing","") -> Missing | K11: =IF(COUNTIF($A$2:$A$2501,A11)>1,"Duplicate","") | L11: =IF(OR(E11=0,E11>10000),"Unusual","") | M11: =IF(OR(ISBLANK(G11),ISERROR(FIND("@",G11)),ISERROR(FIND(".",G11,FIND("@",G11)+1))),"Invalid","") | N11: =IF(COUNTIF($S$2:$S$6,H11)=0,"Invalid","") -> Invalid | O11: =IF(F11<EDATE(TODAY(),-12),"Outdated","") -> Outdated | P11: =IF(ISBLANK(D11),"",PROPER(TRIM(D11))) | Q11: =IF(ISBLANK(D11),"",IF(EXACT(D11,P11),"","Inconsistent"))
A12: R-1010 | B12: Mei Patel | C12: P-260 | D12: Wrong Item | E12: 5315.41 | F12: 45217.667 | G12: mei.patel@example.com | H12: UK | I12: Beauty | J12: =IF(OR(ISBLANK(C12),ISBLANK(D12)),"Missing","") | K12: =IF(COUNTIF($A$2:$A$2501,A12)>1,"Duplicate","") | L12: =IF(OR(E12=0,E12>10000),"Unusual","") | M12: =IF(OR(ISBLANK(G12),ISERROR(FIND("@",G12)),ISERROR(FIND(".",G12,FIND("@",G12)+1))),"Invalid","") | N12: =IF(COUNTIF($S$2:$S$6,H12)=0,"Invalid","") | O12: =IF(F12<EDATE(TODAY(),-12),"Outdated","") -> Outdated | P12: =IF(ISBLANK(D12),"",PROPER(TRIM(D12))) -> Wrong Item | Q12: =IF(ISBLANK(D12),"",IF(EXACT(D12,P12),"","Inconsistent"))
A13: R-2813 | B13: Samuel Gomez | C13: P-121 | D13: Late Delivery | E13: 10188.53 | F13: 45732.667 | G13: samuel.gomez@example.com | I13: Electronics | J13: =IF(OR(ISBLANK(C13),ISBLANK(D13)),"Missing","") | K13: =IF(COUNTIF($A$2:$A$2501,A13)>1,"Duplicate","") -> Duplicate | L13: =IF(OR(E13=0,E13>10000),"Unusual","") -> Unusual | M13: =IF(OR(ISBLANK(G13),ISERROR(FIND("@",G13)),ISERROR(FIND(".",G13,FIND("@",G13)+1))),"Invalid","") | N13: =IF(COUNTIF($S$2:$S$6,H13)=0,"Invalid","") -> Invalid | O13: =IF(F13<EDATE(TODAY(),-12),"Outdated","") -> Outdated | P13: =IF(ISBLANK(D13),"",PROPER(TRIM(D13))) -> Late Delivery | Q13: =IF(ISBLANK(D13),"",IF(EXACT(D13,P13),"","Inconsistent"))
A14: R-1012 | B14: Lucia Khan | D14: Damaged | E14: 11024.97 | F14: 45560.667 | G14: lucia.khan@example.com | H14: Canada | I14: Clothing | J14: =IF(OR(ISBLANK(C14),ISBLANK(D14)),"Missing","") -> Missing | K14: =IF(COUNTIF($A$2:$A$2501,A14)>1,"Duplicate","") | L14: =IF(OR(E14=0,E14>10000),"Unusual","") -> Unusual | M14: =IF(OR(ISBLANK(G14),ISERROR(FIND("@",G14)),ISERROR(FIND(".",G14,FIND("@",G14)+1))),"Invalid","") | N14: =IF(COUNTIF($S$2:$S$6,H14)=0,"Invalid","") | O14: =IF(F14<EDATE(TODAY(),-12),"Outdated","") -> Outdated | P14: =IF(ISBLANK(D14),"",PROPER(TRIM(D14))) -> Damaged | Q14: =IF(ISBLANK(D14),"",IF(EXACT(D14,P14),"","Inconsistent"))
A15: R-2305 | B15: Zara Williams | D15: Damaged | E15: 6585.36 | F15: 45160.667 | G15: zara.williams@example.com | H15: USA | I15: Electronics | J15: =IF(OR(ISBLANK(C15),ISBLANK(D15)),"Missing","") -> Missing | K15: =IF(COUNTIF($A$2:$A$2501,A15)>1,"Duplicate","") -> Duplicate | L15: =IF(OR(E15=0,E15>10000),"Unusual","") | M15: =IF(OR(ISBLANK(G15),ISERROR(FIND("@",G15)),ISERROR(FIND(".",G15,FIND("@",G15)+1))),"Invalid","") | N15: =IF(COUNTIF($S$2:$S$6,H15)=0,"Invalid","") | O15: =IF(F15<EDATE(TODAY(),-12),"Outdated","") -> Outdated | P15: =IF(ISBLANK(D15),"",PROPER(TRIM(D15))) -> Damaged | Q15: =IF(ISBLANK(D15),"",IF(EXACT(D15,P15),"","Inconsistent"))
A16: R-2181 | B16: Lucia Khan | C16: P-610 | D16: Damaged | E16: 6996.81 | F16: 45158.667 | G16: lucia.khan@example.com | H16: Earth | I16: Clothing | J16: =IF(OR(ISBLANK(C16),ISBLANK(D16)),"Missing","") | K16: =IF(COUNTIF($A$2:$A$2501,A16)>1,"Duplicate","") -> Duplicate | L16: =IF(OR(E16=0,E16>10000),"Unusual","") | M16: =IF(OR(ISBLANK(G16),ISERROR(FIND("@",G16)),ISERROR(FIND(".",G16,FIND("@",G16)+1))),"Invalid","") | N16: =IF(COUNTIF($S$2:$S$6,H16)=0,"Invalid","") -> Invalid | O16: =IF(F16<EDATE(TODAY(),-12),"Outdated","") -> Outdated | P16: =IF(ISBLANK(D16),"",PROPER(TRIM(D16))) -> Damaged | Q16: =IF(ISBLANK(D16),"",IF(EXACT(D16,P16),"","Inconsistent"))
A17: R-1015 | B17: Zara Williams | C17: P-575 | D17: Wrong Item | E17: 7924.03 | F17: 45223.667 | G17: zara.williams@example.com | H17: Canaada | I17: Clothing | J17: =IF(OR(ISBLANK(C17),ISBLANK(D17)),"Missing","") | K17: =IF(COUNTIF($A$2:$A$2501,A17)>1,"Duplicate","") | L17: =IF(OR(E17=0,E17>10000),"Unusual","") | M17: =IF(OR(ISBLANK(G17),ISERROR(FIND("@",G17)),ISERROR(FIND(".",G17,FIND("@",G17)+1))),"Invalid","") | N17: =IF(COUNTIF($S$2:$S$6,H17)=0,"Invalid","") -> Invalid | O17: =IF(F17<EDATE(TODAY(),-12),"Outdated","") -> Outdated | P17: =IF(ISBLANK(D17),"",PROPER(TRIM(D17))) -> Wrong Item | Q17: =IF(ISBLANK(D17),"",IF(EXACT(D17,P17),"","Inconsistent"))
A18: R-1016 | B18: Lucia Khan | C18: P-882 | D18: Damaged | E18: 283.1 | F18: 45351.667 | G18: lucia.khan@example.com | H18: Mars | I18: Homeware | J18: =IF(OR(ISBLANK(C18),ISBLANK(D18)),"Missing","") | K18: =IF(COUNTIF($A$2:$A$2501,A18)>1,"Duplicate","") | L18: =IF(OR(E18=0,E18>10000),"Unusual","") | M18: =IF(OR(ISBLANK(G18),ISERROR(FIND("@",G18)),ISERROR(FIND(".",G18,FIND("@",G18)+1))),"Invalid","") | N18: =IF(COUNTIF($S$2:$S$6,H18)=0,"Invalid","") -> Invalid | O18: =IF(F18<EDATE(TODAY(),-12),"Outdated","") -> Outdated | P18: =IF(ISBLANK(D18),"",PROPER(TRIM(D18))) -> Damaged | Q18: =IF(ISBLANK(D18),"",IF(EXACT(D18,P18),"","Inconsistent"))
A19: R-1017 | B19: Lucia Khan | C19: P-786 | D19: Wrong Item | E19: 3590.98 | F19: 45366.667 | G19: lucia.khan@example.com | H19: UAE | I19: Clothing | J19: =IF(OR(ISBLANK(C19),ISBLANK(D19)),"Missing","") | K19: =IF(COUNTIF($A$2:$A$2501,A19)>1,"Duplicate","") -> Duplicate | L19: =IF(OR(E19=0,E19>10000),"Unusual","") | M19: =IF(OR(ISBLANK(G19),ISERROR(FIND("@",G19)),ISERROR(FIND(".",G19,FIND("@",G19)+1))),"Invalid","") | N19: =IF(COUNTIF($S$2:$S$6,H19)=0,"Invalid","") -> Invalid | O19: =IF(F19<EDATE(TODAY(),-12),"Outdated","") -> Outdated | P19: =IF(ISBLANK(D19),"",PROPER(TRIM(D19))) -> Wrong Item | Q19: =IF(ISBLANK(D19),"",IF(EXACT(D19,P19),"","Inconsistent"))
A20: R-1018 | B20: Nina Ivanov | C20: P-975 | D20: Not As Described | E20: 2499.33 | F20: 45645.667 | G20: nina.ivanov@example.com | H20: Mars | I20: Clothing | J20: =IF(OR(ISBLANK(C20),ISBLANK(D20)),"Missing","") | K20: =IF(COUNTIF($A$2:$A$2501,A20)>1,"Duplicate","") | L20: =IF(OR(E20=0,E20>10000),"Unusual","") | M20: =IF(OR(ISBLANK(G20),ISERROR(FIND("@",G20)),ISERROR(FIND(".",G20,FIND("@",G20)+1))),"Invalid","") | N20: =IF(COUNTIF($S$2:$S$6,H20)=0,"Invalid","") -> Invalid | O20: =IF(F20<EDATE(TODAY(),-12),"Outdated","") -> Outdated | P20: =IF(ISBLANK(D20),"",PROPER(TRIM(D20))) -> Not As Described | Q20: =IF(ISBLANK(D20),"",IF(EXACT(D20,P20),"","Inconsistent"))
A21: R-1019 | B21: Omar Silva | C21: P-931 | D21: Damaged | E21: 2274.23 | F21: 45744.667 | G21: omar.silva@example.com | H21: Canada | I21: Books | J21: =IF(OR(ISBLANK(C21),ISBLANK(D21)),"Missing","") | K21: =IF(COUNTIF($A$2:$A$2501,A21)>1,"Duplicate","") | L21: =IF(OR(E21=0,E21>10000),"Unusual","") | M21: =IF(OR(ISBLANK(G21),ISERROR(FIND("@",G21)),ISERROR(FIND(".",G21,FIND("@",G21)+1))),"Invalid","") | N21: =IF(COUNTIF($S$2:$S$6,H21)=0,"Invalid","") | O21: =IF(F21<EDATE(TODAY(),-12),"Outdated","") -> Outdated | P21: =IF(ISBLANK(D21),"",PROPER(TRIM(D21))) -> Damaged | Q21: =IF(ISBLANK(D21),"",IF(EXACT(D21,P21),"","Inconsistent"))
A22: R-1020 | B22: Elena Sato | C22: P-584 | D22: Damaged | E22: 3732.08 | F22: 45155.667 | G22: elena.sato@example.com | H22: Australia | I22: Books | J22: =IF(OR(ISBLANK(C22),ISBLANK(D22)),"Missing","") | K22: =IF(COUNTIF($A$2:$A$2501,A22)>1,"Duplicate","") | L22: =IF(OR(E22=0,E22>10000),"Unusual","") | M22: =IF(OR(ISBLANK(G22),ISERROR(FIND("@",G22)),ISERROR(FIND(".",G22,FIND("@",G22)+1))),"Invalid","") | N22: =IF(COUNTIF($S$2:$S$6,H22)=0,"Invalid","") | O22: =IF(F22<EDATE(TODAY(),-12),"Outdated","") -> Outdated | P22: =IF(ISBLANK(D22),"",PROPER(TRIM(D22))) -> Damaged | Q22: =IF(ISBLANK(D22),"",IF(EXACT(D22,P22),"","Inconsistent"))
A23: R-1021 | B23: Nina Ivanov | C23: P-120 | D23: Wrong item | E23: 9299.14 | F23: 45702.667 | G23: nina.ivanov@example.com | H23: Australia | I23: Clothing | J23: =IF(OR(ISBLANK(C23),ISBLANK(D23)),"Missing","") | K23: =IF(COUNTIF($A$2:$A$2501,A23)>1,"Duplicate","") | L23: =IF(OR(E23=0,E23>10000),"Unusual","") | M23: =IF(OR(ISBLANK(G23),ISERROR(FIND("@",G23)),ISERROR(FIND(".",G23,FIND("@",G23)+1))),"Invalid","") | N23: =IF(COUNTIF($S$2:$S$6,H23)=0,"Invalid","") | O23: =IF(F23<EDATE(TODAY(),-12),"Outdated","") -> Outdated | P23: =IF(ISBLANK(D23),"",PROPER(TRIM(D23))) -> Wrong Item | Q23: =IF(ISBLANK(D23),"",IF(EXACT(D23,P23),"","Inconsistent")) -> Inconsistent
A24: R-1022 | B24: Elena Sato | C24: P-373 | D24: Not As Described | E24: 9568.04 | F24: 45331.667 | G24: elena.sato@example.com | H24: Australia | I24: Books | J24: =IF(OR(ISBLANK(C24),ISBLANK(D24)),"Missing","") | K24: =IF(COUNTIF($A$2:$A$2501,A24)>1,"Duplicate","") | L24: =IF(OR(E24=0,E24>10000),"Unusual","") | M24: =IF(OR(ISBLANK(G24),ISERROR(FIND("@",G24)),ISERROR(FIND(".",G24,FIND("@",G24)+1))),"Invalid","") | N24: =IF(COUNTIF($S$2:$S$6,H24)=0,"Invalid","") | O24: =IF(F24<EDATE(TODAY(),-12),"Outdated","") -> Outdated | P24: =IF(ISBLANK(D24),"",PROPER(TRIM(D24))) -> Not As Described | Q24: =IF(ISBLANK(D24),"",IF(EXACT(D24,P24),"","Inconsistent"))
A25: R-1023 | B25: Nina Ivanov | C25: P-415 | D25: Wrong Item | E25: 10649.3 | F25: 45793.667 | G25: nina.ivanov@example.com | H25: Germany | I25: Homeware | J25: =IF(OR(ISBLANK(C25),ISBLANK(D25)),"Missing","") | K25: =IF(COUNTIF($A$2:$A$2501,A25)>1,"Duplicate","") | L25: =IF(OR(E25=0,E25>10000),"Unusual","") -> Unusual | M25: =IF(OR(ISBLANK(G25),ISERROR(FIND("@",G25)),ISERROR(FIND(".",G25,FIND("@",G25)+1))),"Invalid","") | N25: =IF(COUNTIF($S$2:$S$6,H25)=0,"Invalid","") | O25: =IF(F25<EDATE(TODAY(),-12),"Outdated","") -> Outdated | P25: =IF(ISBLANK(D25),"",PROPER(TRIM(D25))) -> Wrong Item | Q25: =IF(ISBLANK(D25),"",IF(EXACT(D25,P25),"","Inconsistent"))
A26: R-1024 | B26: Kwame Patel | C26: P-876 | D26: DAMAGED | E26: 4036.15 | F26: 45846.667 | G26: kwame.patel@example.com | H26: Germany | I26: Homeware | J26: =IF(OR(ISBLANK(C26),ISBLANK(D26)),"Missing","") | K26: =IF(COUNTIF($A$2:$A$2501,A26)>1,"Duplicate","") | L26: =IF(OR(E26=0,E26>10000),"Unusual","") | M26: =IF(OR(ISBLANK(G26),ISERROR(FIND("@",G26)),ISERROR(FIND(".",G26,FIND("@",G26)+1))),"Invalid","") | N26: =IF(COUNTIF($S$2:$S$6,H26)=0,"Invalid","") | O26: =IF(F26<EDATE(TODAY(),-12),"Outdated","") | P26: =IF(ISBLANK(D26),"",PROPER(TRIM(D26))) -> Damaged | Q26: =IF(ISBLANK(D26),"",IF(EXACT(D26,P26),"","Inconsistent")) -> Inconsistent
A27: R-2141 | B27: Mei Patel | D27: Wrong Item | E27: 1234.86 | F27: 45686.667 | G27: mei.patel@example.com | H27: Mars | I27: Clothing | J27: =IF(OR(ISBLANK(C27),ISBLANK(D27)),"Missing","") -> Missing | K27: =IF(COUNTIF($A$2:$A$2501,A27)>1,"Duplicate","") -> Duplicate | L27: =IF(OR(E27=0,E27>10000),"Unusual","") | M27: =IF(OR(ISBLANK(G27),ISERROR(FIND("@",G27)),ISERROR(FIND(".",G27,FIND("@",G27)+1))),"Invalid","") | N27: =IF(COUNTIF($S$2:$S$6,H27)=0,"Invalid","") -> Invalid | O27: =IF(F27<EDATE(TODAY(),-12),"Outdated","") -> Outdated | P27: =IF(ISBLANK(D27),"",PROPER(TRIM(D27))) -> Wrong Item | Q27: =IF(ISBLANK(D27),"",IF(EXACT(D27,P27),"","Inconsistent"))
A28: R-1026 | B28: Zara Williams | C28: P-191 | D28: Wrong Item | E28: 4646.95 | F28: 45557.667 | G28: zara.williams@example.com | H28: Canaada | I28: Beauty | J28: =IF(OR(ISBLANK(C28),ISBLANK(D28)),"Missing","") | K28: =IF(COUNTIF($A$2:$A$2501,A28)>1,"Duplicate","") | L28: =IF(OR(E28=0,E28>10000),"Unusual","") | M28: =IF(OR(ISBLANK(G28),ISERROR(FIND("@",G28)),ISERROR(FIND(".",G28,FIND("@",G28)+1))),"Invalid","") | N28: =IF(COUNTIF($S$2:$S$6,H28)=0,"Invalid","") -> Invalid | O28: =IF(F28<EDATE(TODAY(),-12),"Outdated","") -> Outdated | P28: =IF(ISBLANK(D28),"",PROPER(TRIM(D28))) -> Wrong Item | Q28: =IF(ISBLANK(D28),"",IF(EXACT(D28,P28),"","Inconsistent"))
A29: R-1027 | B29: Nina Ivanov | C29: P-554 | D29: Not As Described | E29: 5914.76 | F29: 45353.667 | G29: nina.ivanov@example.com | H29: UK | I29: Books | J29: =IF(OR(ISBLANK(C29),ISBLANK(D29)),"Missing","") | K29: =IF(COUNTIF($A$2:$A$2501,A29)>1,"Duplicate","") | L29: =IF(OR(E29=0,E29>10000),"Unusual","") | M29: =IF(OR(ISBLANK(G29),ISERROR(FIND("@",G29)),ISERROR(FIND(".",G29,FIND("@",G29)+1))),"Invalid","") | N29: =IF(COUNTIF($S$2:$S$6,H29)=0,"Invalid","") | O29: =IF(F29<EDATE(TODAY(),-12),"Outdated","") -> Outdated | P29: =IF(ISBLANK(D29),"",PROPER(TRIM(D29))) -> Not As Described | Q29: =IF(ISBLANK(D29),"",IF(EXACT(D29,P29),"","Inconsistent"))
A30: R-1028 | B30: Nina Ivanov | C30: P-875 | D30: Late Delivery | E30: 8817.14 | F30: 45587.667 | G30: nina.ivanov@example.com | H30: Canaada | I30: Toys | J30: =IF(OR(ISBLANK(C30),ISBLANK(D30)),"Missing","") | K30: =IF(COUNTIF($A$2:$A$2501,A30)>1,"Duplicate","") | L30: =IF(OR(E30=0,E30>10000),"Unusual","") | M30: =IF(OR(ISBLANK(G30),ISERROR(FIND("@",G30)),ISERROR(FIND(".",G30,FIND("@",G30)+1))),"Invalid","") | N30: =IF(COUNTIF($S$2:$S$6,H30)=0,"Invalid","") -> Invalid | O30: =IF(F30<EDATE(TODAY(),-12),"Outdated","") -> Outdated | P30: =IF(ISBLANK(D30),"",PROPER(TRIM(D30))) -> Late Delivery | Q30: =IF(ISBLANK(D30),"",IF(EXACT(D30,P30),"","Inconsistent"))
A31: R-2327 | B31: Samuel Gomez | D31: Damaged | E31: 5889.72 | F31: 45731.667 | G31: samuel.gomez@example.com | H31: Australia | I31: Electronics | J31: =IF(OR(ISBLANK(C31),ISBLANK(D31)),"Missing","") -> Missing | K31: =IF(COUNTIF($A$2:$A$2501,A31)>1,"Duplicate","") -> Duplicate | L31: =IF(OR(E31=0,E31>10000),"Unusual","") | M31: =IF(OR(ISBLANK(G31),ISERROR(FIND("@",G31)),ISERROR(FIND(".",G31,FIND("@",G31)+1))),"Invalid","") | N31: =IF(COUNTIF($S$2:$S$6,H31)=0,"Invalid","") | O31: =IF(F31<EDATE(TODAY(),-12),"Outdated","") -> Outdated | P31: =IF(ISBLANK(D31),"",PROPER(TRIM(D31))) -> Damaged | Q31: =IF(ISBLANK(D31),"",IF(EXACT(D31,P31),"","Inconsistent"))
A32: R-1030 | B32: Lucia Khan | C32: P-661 | D32: Wrong Item | E32: 0 | F32: 45412.667 | G32: lucia.khan@example.com | I32: Books | J32: =IF(OR(ISBLANK(C32),ISBLANK(D32)),"Missing","") | K32: =IF(COUNTIF($A$2:$A$2501,A32)>1,"Duplicate","") | L32: =IF(OR(E32=0,E32>10000),"Unusual","") -> Unusual | M32: =IF(OR(ISBLANK(G32),ISERROR(FIND("@",G32)),ISERROR(FIND(".",G32,FIND("@",G32)+1))),"Invalid","") | N32: =IF(COUNTIF($S$2:$S$6,H32)=0,"Invalid","") -> Invalid | O32: =IF(F32<EDATE(TODAY(),-12),"Outdated","") -> Outdated | P32: =IF(ISBLANK(D32),"",PROPER(TRIM(D32))) -> Wrong Item | Q32: =IF(ISBLANK(D32),"",IF(EXACT(D32,P32),"","Inconsistent"))
A33: R-1031 | B33: Kwame Patel | C33: P-101 | D33: Late Delivery | E33: 7990.29 | F33: 45134.667 | G33: kwame.patel@example.com | H33: Australia | I33: Homeware | J33: =IF(OR(ISBLANK(C33),ISBLANK(D33)),"Missing","") | K33: =IF(COUNTIF($A$2:$A$2501,A33)>1,"Duplicate","") | L33: =IF(OR(E33=0,E33>10000),"Unusual","") | M33: =IF(OR(ISBLANK(G33),ISERROR(FIND("@",G33)),ISERROR(FIND(".",G33,FIND("@",G33)+1))),"Invalid","") | N33: =IF(COUNTIF($S$2:$S$6,H33)=0,"Invalid","") | O33: =IF(F33<EDATE(TODAY(),-12),"Outdated","") -> Outdated | P33: =IF(ISBLANK(D33),"",PROPER(TRIM(D33))) -> Late Delivery | Q33: =IF(ISBLANK(D33),"",IF(EXACT(D33,P33),"","Inconsistent"))
A34: R-1032 | B34: Mei Patel | C34: P-665 | D34: Damaged | E34: 11453.07 | F34: 45291.667 | G34: mei.patel@example.com | H34: Germany | I34: Homeware | J34: =IF(OR(ISBLANK(C34),ISBLANK(D34)),"Missing","") | K34: =IF(COUNTIF($A$2:$A$2501,A34)>1,"Duplicate","") | L34: =IF(OR(E34=0,E34>10000),"Unusual","") -> Unusual | M34: =IF(OR(ISBLANK(G34),ISERROR(FIND("@",G34)),ISERROR(FIND(".",G34,FIND("@",G34)+1))),"Invalid","") | N34: =IF(COUNTIF($S$2:$S$6,H34)=0,"Invalid","") | O34: =IF(F34<EDATE(TODAY(),-12),"Outdated","") -> Outdated | P34: =IF(ISBLANK(D34),"",PROPER(TRIM(D34))) -> Damaged | Q34: =IF(ISBLANK(D34),"",IF(EXACT(D34,P34),"","Inconsistent"))
A35: R-1033 | B35: Victor Adu | C35: P-921 | D35: DAMAGED | E35: 8495.29 | F35: 45842.667 | G35: victor.adu@example.com | H35: UAE | I35: Toys | J35: =IF(OR(ISBLANK(C35),ISBLANK(D35)),"Missing","") | K35: =IF(COUNTIF($A$2:$A$2501,A35)>1,"Duplicate","") | L35: =IF(OR(E35=0,E35>10000),"Unusual","") | M35: =IF(OR(ISBLANK(G35),ISERROR(FIND("@",G35)),ISERROR(FIND(".",G35,FIND("@",G35)+1))),"Invalid","") | N35: =IF(COUNTIF($S$2:$S$6,H35)=0,"Invalid","") -> Invalid | O35: =IF(F35<EDATE(TODAY(),-12),"Outdated","") -> Outdated | P35: =IF(ISBLANK(D35),"",PROPER(TRIM(D35))) -> Damaged | Q35: =IF(ISBLANK(D35),"",IF(EXACT(D35,P35),"","Inconsistent")) -> Inconsistent
A36: R-1034 | B36: Nina Ivanov | D36: Wrong Item | E36: 3028.82 | F36: 45560.667 | H36: Australia | I36: Beauty | J36: =IF(OR(ISBLANK(C36),ISBLANK(D36)),"Missing","") -> Missing | K36: =IF(COUNTIF($A$2:$A$2501,A36)>1,"Duplicate","") | L36: =IF(OR(E36=0,E36>10000),"Unusual","") | M36: =IF(OR(ISBLANK(G36),ISERROR(FIND("@",G36)),ISERROR(FIND(".",G36,FIND("@",G36)+1))),"Invalid","") -> Invalid | N36: =IF(COUNTIF($S$2:$S$6,H36)=0,"Invalid","") | O36: =IF(F36<EDATE(TODAY(),-12),"Outdated","") -> Outdated | P36: =IF(ISBLANK(D36),"",PROPER(TRIM(D36))) -> Wrong Item | Q36: =IF(ISBLANK(D36),"",IF(EXACT(D36,P36),"","Inconsistent"))
A37: R-1035 | B37: Victor Adu | C37: P-655 | D37: Wrong item | E37: 2378.48 | F37: 45476.667 | G37: victor.adu@example.com | H37: Canaada | I37: Clothing | J37: =IF(OR(ISBLANK(C37),ISBLANK(D37)),"Missing","") | K37: =IF(COUNTIF($A$2:$A$2501,A37)>1,"Duplicate","") | L37: =IF(OR(E37=0,E37>10000),"Unusual","") | M37: =IF(OR(ISBLANK(G37),ISERROR(FIND("@",G37)),ISERROR(FIND(".",G37,FIND("@",G37)+1))),"Invalid","") | N37: =IF(COUNTIF($S$2:$S$6,H37)=0,"Invalid","") -> Invalid | O37: =IF(F37<EDATE(TODAY(),-12),"Outdated","") -> Outdated | P37: =IF(ISBLANK(D37),"",PROPER(TRIM(D37))) -> Wrong Item | Q37: =IF(ISBLANK(D37),"",IF(EXACT(D37,P37),"","Inconsistent")) -> Inconsistent
A38: R-1036 | B38: Elena Sato | C38: P-369 | D38: Late Delivery | E38: 11993.61 | F38: 45412.667 | G38: elena.sato@example.com | H38: UK | I38: Toys | J38: =IF(OR(ISBLANK(C38),ISBLANK(D38)),"Missing","") | K38: =IF(COUNTIF($A$2:$A$2501,A38)>1,"Duplicate","") | L38: =IF(OR(E38=0,E38>10000),"Unusual","") -> Unusual | M38: =IF(OR(ISBLANK(G38),ISERROR(FIND("@",G38)),ISERROR(FIND(".",G38,FIND("@",G38)+1))),"Invalid","") | N38: =IF(COUNTIF($S$2:$S$6,H38)=0,"Invalid","") | O38: =IF(F38<EDATE(TODAY(),-12),"Outdated","") -> Outdated | P38: =IF(ISBLANK(D38),"",PROPER(TRIM(D38))) -> Late Delivery | Q38: =IF(ISBLANK(D38),"",IF(EXACT(D38,P38),"","Inconsistent"))
A39: R-2750 | B39: Lucia Khan | C39: P-370 | E39: 5171.85 | F39: 45287.667 | H39: Canaada | I39: Toys | J39: =IF(OR(ISBLANK(C39),ISBLANK(D39)),"Missing","") -> Missing | K39: =IF(COUNTIF($A$2:$A$2501,A39)>1,"Duplicate","") -> Duplicate | L39: =IF(OR(E39=0,E39>10000),"Unusual","") | M39: =IF(OR(ISBLANK(G39),ISERROR(FIND("@",G39)),ISERROR(FIND(".",G39,FIND("@",G39)+1))),"Invalid","") -> Invalid | N39: =IF(COUNTIF($S$2:$S$6,H39)=0,"Invalid","") -> Invalid | O39: =IF(F39<EDATE(TODAY(),-12),"Outdated","") -> Outdated | P39: =IF(ISBLANK(D39),"",PROPER(TRIM(D39))) | Q39: =IF(ISBLANK(D39),"",IF(EXACT(D39,P39),"","Inconsistent"))
A40: R-3494 | B40: Victor Adu | C40: P-826 | D40: Not As Described | E40: 7247.05 | F40: 45348.667 | G40: victor.adu@example.com | H40: UK | I40: Electronics | J40: =IF(OR(ISBLANK(C40),ISBLANK(D40)),"Missing","") | K40: =IF(COUNTIF($A$2:$A$2501,A40)>1,"Duplicate","") | L40: =IF(OR(E40=0,E40>10000),"Unusual","") | M40: =IF(OR(ISBLANK(G40),ISERROR(FIND("@",G40)),ISERROR(FIND(".",G40,FIND("@",G40)+1))),"Invalid","") | N40: =IF(COUNTIF($S$2:$S$6,H40)=0,"Invalid","") | O40: =IF(F40<EDATE(TODAY(),-12),"Outdated","") -> Outdated | P40: =IF(ISBLANK(D40),"",PROPER(TRIM(D40))) -> Not As Described | Q40: =IF(ISBLANK(D40),"",IF(EXACT(D40,P40),"","Inconsistent"))
...

Sheet Data Quality Summary
A1: Issue Type | B1: Count
A2: Missing (Product Code / Return Reason) | B2: =COUNTIF('Returns Audit (Solved)'!J2:J2501,"Missing") -> 247
A3: Duplicate Return ID | B3: =COUNTIF('Returns Audit (Solved)'!K2:K2501,"Duplicate") -> 270
A4: Unusual Refund Amount | B4: =COUNTIF('Returns Audit (Solved)'!L2:L2501,"Unusual") -> 610
A5: Invalid Customer Email | B5: =COUNTIF('Returns Audit (Solved)'!M2:M2501,"Invalid") -> 462
A6: Invalid Country | B6: =COUNTIF('Returns Audit (Solved)'!N2:N2501,"Invalid") -> 1378
A7: Outdated Return Date | B7: =COUNTIF('Returns Audit (Solved)'!O2:O2501,"Outdated") -> 2454
A8: Inconsistent Return Reason | B8: =COUNTIF('Returns Audit (Solved)'!Q2:Q2501,"Inconsistent") -> 356
